<?xml version="1.0" encoding="UTF-8" standalone="no"?>
<!DOCTYPE html PUBLIC "-//W3C//DTD XHTML 1.0 Transitional//EN" "http://www.w3.org/TR/xhtml1/DTD/xhtml1-transitional.dtd"><html xmlns="http://www.w3.org/1999/xhtml"><head><meta http-equiv="Content-Type" content="text/html; charset=UTF-8" /><title xmlns="">Unexpected exceptions
        | Elasticsearch.Net and NEST: the .NET clients [7.x]
      | Elastic
    </title><meta name="generator" content="DocBook XSL Stylesheets V1.78.1" /><link rel="home" href="index.html" title="Elasticsearch.Net and NEST: the .NET clients [7.x]" /><link rel="up" href="thrown-exceptions.html" title="Exceptions" /><link rel="prev" href="thrown-exceptions.html" title="Exceptions" /><link rel="next" href="unrecoverable-exceptions.html" title="Unrecoverable exceptions" /><meta xmlns="" name="description" content="Get started with the documentation for Elasticsearch, Kibana, Logstash, Beats, X-Pack, Elastic Cloud, Elasticsearch for Apache Hadoop, and our language clients." /><meta xmlns="" name="DC.type" content="Learn/Docs/Clients/.Net/7.x" /><meta xmlns="" name="DC.subject" content="Clients" /><meta xmlns="" name="DC.identifier" content="7.x" /></head><body><div xmlns="" class="breadcrumbs"><span class="breadcrumb-link"><a href="index.html">Elasticsearch.Net and NEST:  the .NET clients
      [7.x]
    </a></span> » <span class="breadcrumb-link"><a href="api-conventions.html">API Conventions</a></span> » <span class="breadcrumb-link"><a href="thrown-exceptions.html">Exceptions</a></span> » <span class="breadcrumb-node">Unexpected exceptions</span></div><div xmlns="" class="navheader"><span class="prev"><a href="thrown-exceptions.html">
              « 
              Exceptions</a>
           
        </span><span class="next">
           
          <a href="unrecoverable-exceptions.html">Unrecoverable exceptions
               »
            </a></span></div><div class="section"><div class="titlepage"><div><div><h2 class="title"><a id="unexpected-exceptions"></a>Unexpected exceptions<a xmlns="" href="https://github.com/elastic/elasticsearch-net/edit/7.x/docs/client-concepts/connection-pooling/exceptions/unexpected-exceptions.asciidoc" class="edit_me" title="Edit this page on GitHub" rel="nofollow">edit</a></h2></div></div></div><p>When a client call throws an exception that the <code class="literal">IConnection</code> cannot handle, the exception will bubble
out of the client as an <code class="literal">UnexpectedElasticsearchClientException</code>, regardless of whether the client is configured to
throw exceptions or not.</p><p>An <code class="literal">IConnection</code> is in charge of knowing which exceptions it can recover from and those it can’t, and the default <code class="literal">IConnection</code>
in</p><div class="itemizedlist"><ul class="itemizedlist" type="disc"><li class="listitem">Desktop CLR is based on <code class="literal">WebRequest</code> which can and will recover from <code class="literal">WebException</code></li><li class="listitem">Core CLR is based on <code class="literal">HttpClient</code> which can and will recover from <code class="literal">HttpRequestException</code></li></ul></div><p>Other exceptions will be grounds for immediately exiting the pipeline. Let’s demonstrate this
using our Virtual cluster test framework</p><div xmlns="" class="pre_wrapper lang-csharp"><pre xmlns="http://www.w3.org/1999/xhtml" class="programlisting prettyprint lang-csharp">var audit = new Auditor(() =&gt; VirtualClusterWith <a id="CO2-1"></a><i xmlns="" class="conum" data-value="1"></i>
    .Nodes(10)
    .ClientCalls(r =&gt; r.SucceedAlways())
    .ClientCalls(r =&gt; r.OnPort(9201).FailAlways(new Exception("boom!"))) <a id="CO2-2"></a><i xmlns="" class="conum" data-value="2"></i>
    .StaticConnectionPool()
    .Settings(s =&gt; s.DisablePing())
);

audit = await audit.TraceCall(
    new ClientCall {
        { AuditEvent.HealthyResponse, 9200 }, <a id="CO2-3"></a><i xmlns="" class="conum" data-value="3"></i>
    }
);

audit = await audit.TraceUnexpectedException(
    new ClientCall {
        { AuditEvent.BadResponse, 9201 }, <a id="CO2-4"></a><i xmlns="" class="conum" data-value="4"></i>
    },
    (e) =&gt;
    {
        e.FailureReason.Should().Be(PipelineFailure.Unexpected);
        e.InnerException.Should().NotBeNull();
        e.InnerException.Message.Should().Be("boom!");
    }
);</pre></div><div class="calloutlist"><table border="0" summary="Callout list"><tr><td width="5%" valign="top" align="left"><p><a href="#CO2-1"><i xmlns="" class="conum" data-value="1"></i></a> </p></td><td valign="top" align="left"><p>set up a cluster with 10 nodes</p></td></tr><tr><td width="5%" valign="top" align="left"><p><a href="#CO2-2"><i xmlns="" class="conum" data-value="2"></i></a> </p></td><td valign="top" align="left"><p>where node 2 on port 9201 always throws an exception</p></td></tr><tr><td width="5%" valign="top" align="left"><p><a href="#CO2-3"><i xmlns="" class="conum" data-value="3"></i></a> </p></td><td valign="top" align="left"><p>The first call to 9200 returns a healthy response</p></td></tr><tr><td width="5%" valign="top" align="left"><p><a href="#CO2-4"><i xmlns="" class="conum" data-value="4"></i></a> </p></td><td valign="top" align="left"><p>…​but the second call, to 9201, returns a bad response</p></td></tr></table></div><p>Sometimes, an unexpected exception happens further down in the pipeline. In this scenario, we
wrap them inside an <code class="literal">UnexpectedElasticsearchClientException</code> so that information about where
in the pipeline the exception happened is not lost.</p><p>In this next example, a call to 9200 fails with a <code class="literal">WebException</code>.
The call then rolls over to retry on 9201, which throws an hard exception from within <code class="literal">IConnection</code>.
Finally, we assert that we can still see the audit trail for the whole coordinated request.</p><div xmlns="" class="pre_wrapper lang-csharp"><pre xmlns="http://www.w3.org/1999/xhtml" class="programlisting prettyprint lang-csharp">var audit = new Auditor(() =&gt; VirtualClusterWith
    .Nodes(10)
    .ClientCalls(r =&gt; r.OnPort(9200).FailAlways(new System.Net.Http.HttpRequestException("recover"))) <a id="CO3-1"></a><i xmlns="" class="conum" data-value="1"></i>
    .ClientCalls(r =&gt; r.OnPort(9201).FailAlways(new Exception("boom!"))) <a id="CO3-2"></a><i xmlns="" class="conum" data-value="2"></i>
    .StaticConnectionPool()
    .Settings(s =&gt; s.DisablePing())
);

audit = await audit.TraceUnexpectedException(
    new ClientCall {
        { AuditEvent.BadResponse, 9200 },
        { AuditEvent.BadResponse, 9201 }, <a id="CO3-3"></a><i xmlns="" class="conum" data-value="3"></i>
    },
    (e) =&gt;
    {
        e.FailureReason.Should().Be(PipelineFailure.Unexpected);
        e.InnerException.Should().NotBeNull();
        e.InnerException.Message.Should().Be("boom!");
    }
);</pre></div><div class="calloutlist"><table border="0" summary="Callout list"><tr><td width="5%" valign="top" align="left"><p><a href="#CO3-1"><i xmlns="" class="conum" data-value="1"></i></a> </p></td><td valign="top" align="left"><p>calls on 9200 set up to throw a <code class="literal">HttpRequestException</code></p></td></tr><tr><td width="5%" valign="top" align="left"><p><a href="#CO3-2"><i xmlns="" class="conum" data-value="2"></i></a> </p></td><td valign="top" align="left"><p>calls on 9201 set up to throw an <code class="literal">Exception</code></p></td></tr><tr><td width="5%" valign="top" align="left"><p><a href="#CO3-3"><i xmlns="" class="conum" data-value="3"></i></a> </p></td><td valign="top" align="left"><p>Assert that the audit trail for the client call includes the bad response from 9200 and 9201</p></td></tr></table></div><p>An unexpected hard exception on ping and sniff is something we <span class="strong strong"><strong>do</strong></span> try to recover from and failover to retrying on the next node.</p><p>Here, pinging nodes on first use is enabled and the node on port 9200 throws an exception on ping; when this happens,
we still fallover to retry the ping on node on port 9201, where it succeeds.
Following this, the client call on 9201 throws a hard exception that we are not able to recover from</p><div xmlns="" class="pre_wrapper lang-csharp"><pre xmlns="http://www.w3.org/1999/xhtml" class="programlisting prettyprint lang-csharp">var audit = new Auditor(() =&gt; VirtualClusterWith
    .Nodes(10)
    .Ping(r =&gt; r.OnPort(9200).FailAlways(new Exception("ping exception")))
    .Ping(r =&gt; r.OnPort(9201).SucceedAlways())
    .ClientCalls(r =&gt; r.OnPort(9201).FailAlways(new Exception("boom!")))
    .StaticConnectionPool()
    .AllDefaults()
);

audit = await audit.TraceUnexpectedException(
    new ClientCall {
        { AuditEvent.PingFailure, 9200 },
        { AuditEvent.PingSuccess, 9201 },
        { AuditEvent.BadResponse, 9201 },
    },
    e =&gt;
    {
        e.FailureReason.Should().Be(PipelineFailure.Unexpected);

        e.InnerException.Should().NotBeNull();
        e.InnerException.Message.Should().Be("boom!"); <a id="CO4-1"></a><i xmlns="" class="conum" data-value="1"></i>

        e.SeenExceptions.Should().NotBeEmpty(); <a id="CO4-2"></a><i xmlns="" class="conum" data-value="2"></i>
        var pipelineException = e.SeenExceptions.First();
        pipelineException.FailureReason.Should().Be(PipelineFailure.PingFailure);
        pipelineException.InnerException.Message.Should().Be("ping exception");

        var pingException = e.AuditTrail.First(a =&gt; a.Event == AuditEvent.PingFailure).Exception; <a id="CO4-3"></a><i xmlns="" class="conum" data-value="3"></i>
        pingException.Should().NotBeNull();
        pingException.Message.Should().Be("ping exception");
    }
);</pre></div><div class="calloutlist"><table border="0" summary="Callout list"><tr><td width="5%" valign="top" align="left"><p><a href="#CO4-1"><i xmlns="" class="conum" data-value="1"></i></a> </p></td><td valign="top" align="left"><p><code class="literal">InnerException</code> is the exception that brought the request down</p></td></tr><tr><td width="5%" valign="top" align="left"><p><a href="#CO4-2"><i xmlns="" class="conum" data-value="2"></i></a> </p></td><td valign="top" align="left"><p>The hard exception that happened on ping is still available though</p></td></tr><tr><td width="5%" valign="top" align="left"><p><a href="#CO4-3"><i xmlns="" class="conum" data-value="3"></i></a> </p></td><td valign="top" align="left"><p>An exception can be hard to relate back to a point in time, so the exception is also available on the audit trail</p></td></tr></table></div></div><div xmlns="" class="navfooter"><span class="prev"><a href="thrown-exceptions.html">
              « 
              Exceptions</a>
           
        </span><span class="next">
           
          <a href="unrecoverable-exceptions.html">Unrecoverable exceptions
               »
            </a></span></div></body></html>